Workbook
Name SatkerList: 'Lists'!$A$2:$A$3
Name ComponentList: 'Lists'!$B$2:$B$9

Sheet Dashboard
A1: DASHBOARD MONITORING PEMBANGUNAN ZONA INTEGRITAS PROVINSI GORONTALO
A3: Snapshot berdasarkan 2 file LKE yang diunggah • Kriteria WBK: Nilai RB ≥ 75 • Pengungkit ≥ 40 • setiap area pengungkit ≥ 60%
A5: Jumlah Satker Diusulkan 2 | D5: Memenuhi Syarat WBK 2 | G5: Rata-rata Nilai RB 88.19 | J5: Rata-rata Tindak Lanjut 0.43%
A10: Tindak Lanjut per Satker | H10: Peringkat Nilai Satker
H11: Peringkat | I11: Satker | J11: Nilai RB | K11: Pengungkit | L11: Min Area | M11: TL % | N11: Status
H12: 1 | I12: Kanwil BPN Provinsi Gorontalo | J12: 93.641667 | K12: 53.991667 | L12: 0.64285714 | M12: 0.0085470085 | N12: MEMENUHI
H13: 2 | I13: Kantah Kabupaten Gorontalo | J13: 82.740708 | K13: 45.437583 | L13: 0.603625 | M13: 0 | N13: MEMENUHI
H16: Kriteria Status Memenuhi Syarat WBK
H17: Nilai RB | I17: ≥ 75
H18: Nilai Pengungkit | I18: ≥ 40
H19: Setiap Area Pengungkit | I19: ≥ 60%
H21: Catatan: persentase tindak lanjut dihitung dari checklist pada 3 status per poin LKE: Perbaikan Catatan TPI, Eviden 2024–2025, dan Kesesuaian Penamaan Eviden. Baris total/agregat tidak dihitung.
A27: Satker | B27: TL %
A28: Kantah Kabupaten Gorontalo | B28: 0
A29: Kanwil BPN Provinsi Gorontalo | B29: 0.0085470085

Sheet Progress ZI Satker
A1: PROGRESS PEMBANGUNAN ZI SATKER
A4: Pilih Satker | B4: Kantah Kabupaten Gorontalo | D4: Kriteria | E4: WBK: RB ≥75 | Pengungkit ≥40 | setiap area ≥60%
A6: Nilai RB | C6: Pengungkit | E6: Hasil | G6: Status
A7: =INDEX(Data_Satker!$C$2:$C$100,MATCH($B$4,Data_Satker!$A$2:$A$100,0)) | C7: =INDEX(Data_Satker!$D$2:$D$100,MATCH($B$4,Data_Satker!$A$2:$A$100,0)) | E7: =INDEX(Data_Satker!$F$2:$F$100,MATCH($B$4,Data_Satker!$A$2:$A$100,0)) | G7: =INDEX(Data_Satker!$B$2:$B$100,MATCH($B$4,Data_Satker!$A$2:$A$100,0))
A10: 1. Nilai Area Perubahan & Komponen Hasil | H10: 2. Status Tindak Lanjut per Komponen
A11: No. | B11: Komponen | C11: Bobot | D11: Nilai | E11: % Capaian | F11: Status | H11: Komponen | I11: Total Poin | J11: Catatan TPI | K11: Eviden 2024-2025 | L11: Penamaan Eviden | M11: Total Checklist | N11: TL % | O11: Status
A12: 1 | B12: MANAJEMEN PERUBAHAN | C12: 8 | D12: =SUMIFS(Data_Area!$F:$F,Data_Area!$A:$A,$B$4,Data_Area!$B:$B,"PENGUNGKIT",Data_Area!$C:$C,$A12) | E12: =SUMIFS(Data_Area!$G:$G,Data_Area!$A:$A,$B$4,Data_Area!$B:$B,"PENGUNGKIT",Data_Area!$C:$C,$A12) | F12: =IF(E12>=60%,"OK","< 60%") | H12: MANAJEMEN PERUBAHAN | I12: =COUNTIFS(Data_Poin!$A:$A,$B$4,Data_Poin!$D:$D,$H12) | J12: =COUNTIFS(Data_Poin!$A:$A,$B$4,Data_Poin!$D:$D,$H12,Data_Poin!$M:$M,"✓") | K12: =COUNTIFS(Data_Poin!$A:$A,$B$4,Data_Poin!$D:$D,$H12,Data_Poin!$N:$N,"✓") | L12: =COUNTIFS(Data_Poin!$A:$A,$B$4,Data_Poin!$D:$D,$H12,Data_Poin!$O:$O,"✓") | M12: =J12+K12+L12 | N12: =IF(I12=0,0,M12/(I12*3)) | O12: =IF(N12=100%,"SELESAI","BELUM SELESAI")
A13: 2 | B13: PENATAAN TATALAKSANA | C13: 7 | D13: =SUMIFS(Data_Area!$F:$F,Data_Area!$A:$A,$B$4,Data_Area!$B:$B,"PENGUNGKIT",Data_Area!$C:$C,$A13) | E13: =SUMIFS(Data_Area!$G:$G,Data_Area!$A:$A,$B$4,Data_Area!$B:$B,"PENGUNGKIT",Data_Area!$C:$C,$A13) | F13: =IF(E13>=60%,"OK","< 60%") | H13: PENATAAN TATALAKSANA | I13: =COUNTIFS(Data_Poin!$A:$A,$B$4,Data_Poin!$D:$D,$H13) | J13: =COUNTIFS(Data_Poin!$A:$A,$B$4,Data_Poin!$D:$D,$H13,Data_Poin!$M:$M,"✓") | K13: =COUNTIFS(Data_Poin!$A:$A,$B$4,Data_Poin!$D:$D,$H13,Data_Poin!$N:$N,"✓") | L13: =COUNTIFS(Data_Poin!$A:$A,$B$4,Data_Poin!$D:$D,$H13,Data_Poin!$O:$O,"✓") | M13: =J13+K13+L13 | N13: =IF(I13=0,0,M13/(I13*3)) | O13: =IF(N13=100%,"SELESAI","BELUM SELESAI")
A14: 3 | B14: PENATAAN SISTEM MANAJEMEN SDM APARATUR | C14: 10 | D14: =SUMIFS(Data_Area!$F:$F,Data_Area!$A:$A,$B$4,Data_Area!$B:$B,"PENGUNGKIT",Data_Area!$C:$C,$A14) | E14: =SUMIFS(Data_Area!$G:$G,Data_Area!$A:$A,$B$4,Data_Area!$B:$B,"PENGUNGKIT",Data_Area!$C:$C,$A14) | F14: =IF(E14>=60%,"OK","< 60%") | H14: PENATAAN SISTEM MANAJEMEN SDM APARATUR | I14: =COUNTIFS(Data_Poin!$A:$A,$B$4,Data_Poin!$D:$D,$H14) | J14: =COUNTIFS(Data_Poin!$A:$A,$B$4,Data_Poin!$D:$D,$H14,Data_Poin!$M:$M,"✓") | K14: =COUNTIFS(Data_Poin!$A:$A,$B$4,Data_Poin!$D:$D,$H14,Data_Poin!$N:$N,"✓") | L14: =COUNTIFS(Data_Poin!$A:$A,$B$4,Data_Poin!$D:$D,$H14,Data_Poin!$O:$O,"✓") | M14: =J14+K14+L14 | N14: =IF(I14=0,0,M14/(I14*3)) | O14: =IF(N14=100%,"SELESAI","BELUM SELESAI")
A15: 4 | B15: PENGUATAN AKUNTABILITAS | C15: 10 | D15: =SUMIFS(Data_Area!$F:$F,Data_Area!$A:$A,$B$4,Data_Area!$B:$B,"PENGUNGKIT",Data_Area!$C:$C,$A15) | E15: =SUMIFS(Data_Area!$G:$G,Data_Area!$A:$A,$B$4,Data_Area!$B:$B,"PENGUNGKIT",Data_Area!$C:$C,$A15) | F15: =IF(E15>=60%,"OK","< 60%") | H15: PENGUATAN AKUNTABILITAS | I15: =COUNTIFS(Data_Poin!$A:$A,$B$4,Data_Poin!$D:$D,$H15) | J15: =COUNTIFS(Data_Poin!$A:$A,$B$4,Data_Poin!$D:$D,$H15,Data_Poin!$M:$M,"✓") | K15: =COUNTIFS(Data_Poin!$A:$A,$B$4,Data_Poin!$D:$D,$H15,Data_Poin!$N:$N,"✓") | L15: =COUNTIFS(Data_Poin!$A:$A,$B$4,Data_Poin!$D:$D,$H15,Data_Poin!$O:$O,"✓") | M15: =J15+K15+L15 | N15: =IF(I15=0,0,M15/(I15*3)) | O15: =IF(N15=100%,"SELESAI","BELUM SELESAI")
A16: 5 | B16: PENGUATAN PENGAWASAN | C16: 15 | D16: =SUMIFS(Data_Area!$F:$F,Data_Area!$A:$A,$B$4,Data_Area!$B:$B,"PENGUNGKIT",Data_Area!$C:$C,$A16) | E16: =SUMIFS(Data_Area!$G:$G,Data_Area!$A:$A,$B$4,Data_Area!$B:$B,"PENGUNGKIT",Data_Area!$C:$C,$A16) | F16: =IF(E16>=60%,"OK","< 60%") | H16: PENGUATAN PENGAWASAN | I16: =COUNTIFS(Data_Poin!$A:$A,$B$4,Data_Poin!$D:$D,$H16) | J16: =COUNTIFS(Data_Poin!$A:$A,$B$4,Data_Poin!$D:$D,$H16,Data_Poin!$M:$M,"✓") | K16: =COUNTIFS(Data_Poin!$A:$A,$B$4,Data_Poin!$D:$D,$H16,Data_Poin!$N:$N,"✓") | L16: =COUNTIFS(Data_Poin!$A:$A,$B$4,Data_Poin!$D:$D,$H16,Data_Poin!$O:$O,"✓") | M16: =J16+K16+L16 | N16: =IF(I16=0,0,M16/(I16*3)) | O16: =IF(N16=100%,"SELESAI","BELUM SELESAI")
A17: 6 | B17: PENINGKATAN KUALITAS PELAYANAN PUBLIK | C17: 10 | D17: =SUMIFS(Data_Area!$F:$F,Data_Area!$A:$A,$B$4,Data_Area!$B:$B,"PENGUNGKIT",Data_Area!$C:$C,$A17) | E17: =SUMIFS(Data_Area!$G:$G,Data_Area!$A:$A,$B$4,Data_Area!$B:$B,"PENGUNGKIT",Data_Area!$C:$C,$A17) | F17: =IF(E17>=60%,"OK","< 60%") | H17: PENINGKATAN KUALITAS PELAYANAN PUBLIK | I17: =COUNTIFS(Data_Poin!$A:$A,$B$4,Data_Poin!$D:$D,$H17) | J17: =COUNTIFS(Data_Poin!$A:$A,$B$4,Data_Poin!$D:$D,$H17,Data_Poin!$M:$M,"✓") | K17: =COUNTIFS(Data_Poin!$A:$A,$B$4,Data_Poin!$D:$D,$H17,Data_Poin!$N:$N,"✓") | L17: =COUNTIFS(Data_Poin!$A:$A,$B$4,Data_Poin!$D:$D,$H17,Data_Poin!$O:$O,"✓") | M17: =J17+K17+L17 | N17: =IF(I17=0,0,M17/(I17*3)) | O17: =IF(N17=100%,"SELESAI","BELUM SELESAI")
H18: BIROKRASI YANG BERSIH DAN AKUNTABEL | I18: =COUNTIFS(Data_Poin!$A:$A,$B$4,Data_Poin!$D:$D,$H18) | J18: =COUNTIFS(Data_Poin!$A:$A,$B$4,Data_Poin!$D:$D,$H18,Data_Poin!$M:$M,"✓") | K18: =COUNTIFS(Data_Poin!$A:$A,$B$4,Data_Poin!$D:$D,$H18,Data_Poin!$N:$N,"✓") | L18: =COUNTIFS(Data_Poin!$A:$A,$B$4,Data_Poin!$D:$D,$H18,Data_Poin!$O:$O,"✓") | M18: =J18+K18+L18 | N18: =IF(I18=0,0,M18/(I18*3)) | O18: =IF(N18=100%,"SELESAI","BELUM SELESAI")
A19: Komponen Hasil | H19: PELAYANAN PUBLIK YANG PRIMA | I19: =COUNTIFS(Data_Poin!$A:$A,$B$4,Data_Poin!$D:$D,$H19) | J19: =COUNTIFS(Data_Poin!$A:$A,$B$4,Data_Poin!$D:$D,$H19,Data_Poin!$M:$M,"✓") | K19: =COUNTIFS(Data_Poin!$A:$A,$B$4,Data_Poin!$D:$D,$H19,Data_Poin!$N:$N,"✓") | L19: =COUNTIFS(Data_Poin!$A:$A,$B$4,Data_Poin!$D:$D,$H19,Data_Poin!$O:$O,"✓") | M19: =J19+K19+L19 | N19: =IF(I19=0,0,M19/(I19*3)) | O19: =IF(N19=100%,"SELESAI","BELUM SELESAI")
A20: B.1 | B20: BIROKRASI YANG BERSIH DAN AKUNTABEL | C20: 22.5 | D20: =SUMIFS(Data_Area!$F:$F,Data_Area!$A:$A,$B$4,Data_Area!$B:$B,"HASIL",Data_Area!$C:$C,"1") | E20: =SUMIFS(Data_Area!$G:$G,Data_Area!$A:$A,$B$4,Data_Area!$B:$B,"HASIL",Data_Area!$C:$C,"1") | F20: ="-"
A21: B.2 | B21: PELAYANAN PUBLIK YANG PRIMA | C21: 17.5 | D21: =SUMIFS(Data_Area!$F:$F,Data_Area!$A:$A,$B$4,Data_Area!$B:$B,"HASIL",Data_Area!$C:$C,"2") | E21: =SUMIFS(Data_Area!$G:$G,Data_Area!$A:$A,$B$4,Data_Area!$B:$B,"HASIL",Data_Area!$C:$C,"2") | F21: ="-"
A23: 3. Detail Tindak Lanjut per Poin LKE
A24: Pilih Komponen | B24: MANAJEMEN PERUBAHAN | D24: Pilih komponen di atas untuk menampilkan status pada level poin terkecil (contoh: A.1.i.a).
A26: Code | B26: Indikator | C26: Catatan TPI | D26: Eviden 2024-2025 | E26: Penamaan Eviden | F26: PIC | G26: Link Eviden
A27: =FILTER(CHOOSECOLS(Data_Poin!$A$2:$R$1000,7,8,13,14,15,16,17),(Data_Poin!$A$2:$A$1000=$B$4)*(Data_Poin!$D$2:$D$1000=$B$24),"Tidak ada data")

Sheet Admin
A1: ADMIN / PANDUAN PEMUTAKHIRAN DATA
A4: Workbook ini adalah snapshot dashboard berdasarkan file LKE yang tersedia.
A5: Untuk kebutuhan upload file baru, penambahan satker, dan akses hanya untuk admin, gunakan aplikasi web yang disertakan bersama workbook ini.
A6: Pada aplikasi web: viewer dapat melihat Dashboard dan Progress; menu Admin meminta password sebelum fitur upload ditampilkan.
A7: Upload satu atau beberapa file LKE .xlsx. Nama satker dapat dikoreksi sebelum data disimpan. Jika nama satker sudah ada, data akan diperbarui; jika belum ada, satker baru ditambahkan.
A8: Persentase tindak lanjut dihitung dari 3 checklist pada setiap poin: Perbaikan Catatan TPI, Eviden 2024-2025, dan Kesesuaian Penamaan Eviden. Baris total/agregat tidak dihitung.
A9: Kriteria status WBK pada dashboard: Nilai RB ≥75, Nilai Pengungkit ≥40, dan nilai minimal setiap area pengungkit ≥60%.
A12: Catatan keamanan
A13: Login tidak perlu untuk viewer. Untuk aplikasi yang dipublikasikan, login diperlukan khusus admin karena admin dapat mengubah data dashboard. Prototype web menggunakan password admin yang disimpan di secrets/environment variable, bukan ditulis di kode.

Sheet Data_Satker
A1: Satker | B1: Status WBK | C1: Nilai RB | D1: Nilai Pengungkit | E1: % Pengungkit | F1: Nilai Hasil | G1: % Hasil | H1: Min % Area Pengungkit | I1: TL % Total | J1: TL % Catatan TPI | K1: TL % Eviden 2024-2025 | L1: TL % Penamaan Eviden | M1: Last Updated | N1: Source File
A2: Kantah Kabupaten Gorontalo | B2: MEMENUHI | C2: 82.740708 | D2: 45.437583 | E2: 0.75729306 | F2: 37.303125 | G2: 0.93257813 | H2: 0.603625 | I2: 0 | J2: 0 | K2: 0 | L2: 0 | M2: 46281 | N2: LKE Kantah Kab Gorontalo.xlsx
A3: Kanwil BPN Provinsi Gorontalo | B3: MEMENUHI | C3: 93.641667 | D3: 53.991667 | E3: 0.89986111 | F3: 39.65 | G3: 0.99125 | H3: 0.64285714 | I3: 0.0085470085 | J3: 0.0085470085 | K3: 0.0085470085 | L3: 0.0085470085 | M3: 46281 | N3: LKE Kanwil BPN Gorontalo 2026. (1).xlsx

Sheet Data_Poin
A1: Satker | B1: Section | C1: Component No | D1: Component | E1: Sub No | F1: Subcomponent | G1: Code | H1: Indicator | I1: Answer | J1: Score | K1: Score % | L1: Catatan TPI | M1: TL Catatan TPI | N1: TL Eviden 2024-2025 | O1: TL Penamaan Eviden | P1: PIC | Q1: Link Eviden | R1: Source Row
A2: Kantah Kabupaten Gorontalo | B2: PENGUNGKIT | C2: 1 | D2: MANAJEMEN PERUBAHAN | E2: i | F2: Penyusunan Tim Kerja | G2: A.1.i.a | H2: Unit kerja telah membentuk tim untuk melakukan pembangunan Zona Integritas | I2: Ya | J2: 1 | L2: Belum ada SK ZI Tahun 2025 dan Struktur Keanggotaan ZI 2 tahun terakhir | M2: — | N2: — | O2: — | Q2: https://drive.google.com/drive/folders/1RhMfo0BLlXs55gHJix-hLiYdLfTqX-qX | R2: 6
A3: Kantah Kabupaten Gorontalo | B3: PENGUNGKIT | C3: 1 | D3: MANAJEMEN PERUBAHAN | E3: i | F3: Penyusunan Tim Kerja | G3: A.1.i.b | H3: Penentuan anggota Tim dipilih melalui prosedur/mekanisme yang jelas | I3: B | J3: 0.5 | L3: Belum ada evidence 2025 | M3: — | N3: — | O3: — | Q3: https://drive.google.com/drive/folders/1vLl4DAtUEjNdlleP4v7WHm8A3Fcczt2R?usp=sharing | R3: 7
A4: Kantah Kabupaten Gorontalo | B4: PENGUNGKIT | C4: 1 | D4: MANAJEMEN PERUBAHAN | E4: ii | F4: Rencana Pembangunan Zona Integritas | G4: A.1.ii.a | H4: Terdapat dokumen rencana kerja pembangunan Zona Integritas menuju WBK/WBBM | I4: Ya | J4: 1 | L4: ND dan Dokumentasi Kegiatan sama dengan Rapat Persiapan Pembentukan Tim Kerja ZI, belum ada SK, seluruh evidence hanya 2026 | M4: — | N4: — | O4: — | Q4: https://drive.google.com/drive/folders/112yvNGRWmWgBVyV7YMlp3-W9jXnuzx4Z | R4: 9
A5: Kantah Kabupaten Gorontalo | B5: PENGUNGKIT | C5: 1 | D5: MANAJEMEN PERUBAHAN | E5: ii | F5: Rencana Pembangunan Zona Integritas | G5: A.1.ii.b | H5: Dalam dokumen pembangunan terdapat target-target prioritas yang relevan dengan tujuan pembangunan WBK/WBBM | I5: B | J5: 0.5 | L5: Belum ada evidence tahun 2025 | M5: — | N5: — | O5: — | Q5: https://drive.google.com/drive/folders/1Soofqpin-xpZFCfl3sVumnauZJNg8K1X | R5: 10
A6: Kantah Kabupaten Gorontalo | B6: PENGUNGKIT | C6: 1 | D6: MANAJEMEN PERUBAHAN | E6: ii | F6: Rencana Pembangunan Zona Integritas | G6: A.1.ii.c | H6: Terdapat mekanisme atau media untuk mensosialisasikan pembangunan WBK/WBBM | I6: B | J6: 0.5 | L6: Belum ada evidence tahun 2025 | M6: — | N6: — | O6: — | Q6: https://drive.google.com/drive/folders/1BCOZnAXsj_NaFRGr2FFxMD3VAUOW3K3M | R6: 11
A7: Kantah Kabupaten Gorontalo | B7: PENGUNGKIT | C7: 1 | D7: MANAJEMEN PERUBAHAN | E7: iii | F7: Pemantauan dan Evaluasi Pembangunan WBK/WBBM | G7: A.1.iii.a | H7: Seluruh kegiatan pembangunan sudah dilaksanakan sesuai dengan rencana | I7: B | J7: 0.67 | L7: Belum ada evidence tahun 2025 | M7: — | N7: — | O7: — | Q7: https://drive.google.com/drive/folders/1NxoVHvgD_pluHTC7VDnT8t07k5BFQ-QG | R7: 13
A8: Kantah Kabupaten Gorontalo | B8: PENGUNGKIT | C8: 1 | D8: MANAJEMEN PERUBAHAN | E8: iii | F8: Pemantauan dan Evaluasi Pembangunan WBK/WBBM | G8: A.1.iii.b | H8: Terdapat monitoring dan evaluasi terhadap pembangunan Zona Integritas | I8: B | J8: 0.67 | L8: Belum ada evidence tahun 2025 | M8: — | N8: — | O8: — | Q8: https://drive.google.com/drive/folders/1OFRWjSjBrjFscq9vQsK9LfQPLT8OhaWw | R8: 14
A9: Kantah Kabupaten Gorontalo | B9: PENGUNGKIT | C9: 1 | D9: MANAJEMEN PERUBAHAN | E9: iii | F9: Pemantauan dan Evaluasi Pembangunan WBK/WBBM | G9: A.1.iii.c | H9: Hasil Monitoring dan Evaluasi telah ditindaklanjuti | I9: B | J9: 0.67 | L9: Isi uraian evidence , evidence 2025 belum ada | M9: — | N9: — | O9: — | Q9: https://drive.google.com/drive/folders/1xCQGEfrGQrmFCHENH9lpC1sXQsAGAXsy | R9: 15
A10: Kantah Kabupaten Gorontalo | B10: PENGUNGKIT | C10: 1 | D10: MANAJEMEN PERUBAHAN | E10: iv | F10: Perubahan pola pikir dan budaya kerja | G10: A.1.iv.a | H10: Pimpinan berperan sebagai role model dalam pelaksanaan Pembangunan WBK/WBBM | I10: Ya | J10: 1 | L10: Evidence belum ada 2025 | M10: — | N10: — | O10: — | Q10: https://drive.google.com/drive/folders/1-0EFVL2GitmA9pwmd0hamZuBGi38l7U4 | R10: 17
A11: Kantah Kabupaten Gorontalo | B11: PENGUNGKIT | C11: 1 | D11: MANAJEMEN PERUBAHAN | E11: iv | F11: Perubahan pola pikir dan budaya kerja | G11: A.1.iv.b | H11: Sudah ditetapkan agen perubahan | I11: B | J11: 0.5 | L11: Belum ada penetapan Agen Perubahan 2025 - 2026 | M11: — | N11: — | O11: — | Q11: https://drive.google.com/drive/folders/15ZSHAYgymJxsTX6KaCzfjw4QtgcAznf8?usp=sharing | R11: 18
A12: Kantah Kabupaten Gorontalo | B12: PENGUNGKIT | C12: 1 | D12: MANAJEMEN PERUBAHAN | E12: iv | F12: Perubahan pola pikir dan budaya kerja | G12: A.1.iv.c | H12: Telah dibangun budaya kerja dan pola pikir di lingkungan organisasi | I12: B | J12: 0.5 | L12: belum ada evidence 2025 | M12: — | N12: — | O12: — | Q12: https://drive.google.com/drive/folders/1dNOTekTSjFGqhzBGSHzUW9PgnPj9y8tE | R12: 19
A13: Kantah Kabupaten Gorontalo | B13: PENGUNGKIT | C13: 1 | D13: MANAJEMEN PERUBAHAN | E13: iv | F13: Perubahan pola pikir dan budaya kerja | G13: A.1.iv.d | H13: Anggota organisasi terlibat dalam pembangunan Zona Integritas menuju WBK/WBBM | I13: B | J13: 0.67 | L13: belum ada 2025 | M13: — | N13: — | O13: — | Q13: https://drive.google.com/drive/folders/1QP7oS6rInecNcyr9VvyJLRR1IdMbhF_7?usp=sharing | R13: 20
A14: Kantah Kabupaten Gorontalo | B14: PENGUNGKIT | C14: 2 | D14: PENATAAN TATALAKSANA | E14: i | F14: Prosedur Operasional Tetap (SOP) Kegiatan Utama | G14: A.2.i.a | H14: SOP mengacu pada peta proses bisnis instansi | I14: B | J14: 0.67 | L14: - Folder Monev Layanan masih kosong | M14: — | N14: — | O14: — | Q14: https://drive.google.com/drive/folders/16kQZal62HcQzELSoOJqwDsmm0h2TWTcY | R14: 23
A15: Kantah Kabupaten Gorontalo | B15: PENGUNGKIT | C15: 2 | D15: PENATAAN TATALAKSANA | E15: i | F15: Prosedur Operasional Tetap (SOP) Kegiatan Utama | G15: A.2.i.b | H15: Prosedur operasional tetap (SOP) telah diterapkan | I15: A | J15: 1 | M15: — | N15: — | O15: — | Q15: https://drive.google.com/drive/folders/1wB5GZagympLlTZlueZTK7clhylQ2xPjU | R15: 24
A16: Kantah Kabupaten Gorontalo | B16: PENGUNGKIT | C16: 2 | D16: PENATAAN TATALAKSANA | E16: i | F16: Prosedur Operasional Tetap (SOP) Kegiatan Utama | G16: A.2.i.c | H16: Prosedur operasional tetap (SOP) telah dievaluasi | I16: C | J16: 0.5 | L16: - Laporan tindak lanjut hasil evaluasi belum diupload | M16: — | N16: — | O16: — | Q16: https://drive.google.com/drive/folders/1vzz6pWXA_FmvN8QwSnT--0P3JXo_7kOZ | R16: 25
A17: Kantah Kabupaten Gorontalo | B17: PENGUNGKIT | C17: 2 | D17: PENATAAN TATALAKSANA | E17: ii | F17: Sistem Pemerintahan Berbasis Elektronik (SPBE) | G17: A.2.ii.a | H17: Sistem pengukuran kinerja unit sudah menggunakan teknologi informasi | I17: B | J17: 0.5 | L17: - Absensi Fingerprint belum diupload - inovasi aplikasi yang ada belum diupload | M17: — | N17: — | O17: — | Q17: ii. a. Sistem pengukuran kinerja unit sudah menggunakan teknologi informasi | R17: 27
A18: Kantah Kabupaten Gorontalo | B18: PENGUNGKIT | C18: 2 | D18: PENATAAN TATALAKSANA | E18: ii | F18: Sistem Pemerintahan Berbasis Elektronik (SPBE) | G18: A.2.ii.b | H18: Operasionalisasi manajemen SDM sudah menggunakan teknologi informasi | I18: A | J18: 1 | M18: — | N18: — | O18: — | Q18: https://drive.google.com/drive/folders/1JQedP6XgrafY4FoBKZDxRHtRLbgaJZos | R18: 28
A19: Kantah Kabupaten Gorontalo | B19: PENGUNGKIT | C19: 2 | D19: PENATAAN TATALAKSANA | E19: ii | F19: Sistem Pemerintahan Berbasis Elektronik (SPBE) | G19: A.2.ii.c | H19: Pemberian pelayanan kepada publik sudah menggunakan teknologi informasi | I19: B | J19: 0.5 | L19: - inovasi aplikasi yang ada belum diupload | M19: — | N19: — | O19: — | Q19: https://drive.google.com/drive/folders/1BjHaPYl96KzGy56lGuobDR6fqro8Do3b | R19: 29
A20: Kantah Kabupaten Gorontalo | B20: PENGUNGKIT | C20: 2 | D20: PENATAAN TATALAKSANA | E20: ii | F20: Sistem Pemerintahan Berbasis Elektronik (SPBE) | G20: A.2.ii.d | H20: Telah dilakukan monitoring dan dan evaluasi terhadap pemanfaatan teknologi informasi dalam pengukuran kinerja unit, operasionalisasi SDM, dan pemberian layanan kepada publik | I20: B | J20: 0.5 | L20: - Laporan Monitoring dan Evaluasi terkait teknologi aplikasi layanan belum diupload - Laporan IKM belum dibuat secara periodik | M20: — | N20: — | O20: — | Q20: https://drive.google.com/drive/folders/1Lhp_xEug90r9-jLogqp0OPVRZbAbyGZh | R20: 30
A21: Kantah Kabupaten Gorontalo | B21: PENGUNGKIT | C21: 2 | D21: PENATAAN TATALAKSANA | E21: iii | F21: Keterbukaan Informasi Publik | G21: A.2.iii.a | H21: Kebijakan tentang keterbukaan informasi publik telah diterapkan | I21: A | J21: 1 | M21: — | N21: — | O21: — | Q21: https://drive.google.com/drive/folders/1UkBXMqN-hVghI3KocSpsOUQus192fa3P | R21: 32
A22: Kantah Kabupaten Gorontalo | B22: PENGUNGKIT | C22: 2 | D22: PENATAAN TATALAKSANA | E22: iii | F22: Keterbukaan Informasi Publik | G22: A.2.iii.b | H22: Telah dilakukan monitoring dan evaluasi pelaksanaan kebijakan keterbukaan informasi publik | I22: B | J22: 0.5 | L22: Laporan tindak lanjut hasil evaluasi belum diupload | M22: — | N22: — | O22: — | Q22: https://drive.google.com/drive/folders/1HzJbYuqijjIhOi9m1Ihs0FjbDOIvomdh | R22: 33
A23: Kantah Kabupaten Gorontalo | B23: PENGUNGKIT | C23: 3 | D23: PENATAAN SISTEM MANAJEMEN SDM APARATUR | E23: i | F23: Perencanaan Kebutuhan Pegawai sesuai dengan Kebutuhan Organisasi | G23: A.3.i.a | H23: Kebutuhan pegawai yang disusun oleh unit kerja mengacu kepada peta jabatan dan hasil analisis beban kerja untuk masing-masing jabatan | I23: Ya | J23: 1 | L23: Belum ada eviden diupload. Eviden diuraikan di kolom Cararan/Keterangan/Penjelasan Unit. Bisa dilampirkan: 1. ABK 2. Peta Jabatan 3.Surat Kakanwil terkait dengan penyampaian analisa kebutuhan jabatan 4. Formulir perhitungan beban kerja 5.Dokumentasi Rapat terkait Analisis Beban Kerja (Undangan, Daftar Hadir, Foto, Notulen) 6. Laporan Rencana Kebutuhan Pegawai 7.Laporan Analisa Kebutuhan Pegawai 8. Bagan Organisasi | M23: — | N23: — | O23: — | Q23: https://drive.google.com/drive/folders/1M7Vcj_XMMihfkYHp4AggE-4tXLWHBPTN | R23: 36
A24: Kantah Kabupaten Gorontalo | B24: PENGUNGKIT | C24: 3 | D24: PENATAAN SISTEM MANAJEMEN SDM APARATUR | E24: i | F24: Perencanaan Kebutuhan Pegawai sesuai dengan Kebutuhan Organisasi | G24: A.3.i.b | H24: Penempatan pegawai hasil rekrutmen murni mengacu kepada kebutuhan pegawai yang telah disusun per jabatan | I24: B | J24: 0.67 | L24: Belum ada eviden diupload. Eviden diuraikan di kolom Cararan/Keterangan/Penjelasan Unit. Bisa dilampirkan: 1. ABK JFT/JFU 2. Peta Jabatan 3.Surat Kakanwil terkait dengan penyampaian analisa kebutuhan jabatan 4. Rapat Kebutuhan pegawai (undangan, daftar hadir, notulen) 5. Kontrak PPNPN 2025 6.SK penempatan PNS dan CPNS, ST pegawai dari kanwil, berita acara surat tugas | M24: — | N24: — | O24: — | Q24: https://drive.google.com/drive/folders/1yRvNfcfdY3ilxGGdhpsJWiZ2uiMQ6YAN | R24: 37
A25: Kantah Kabupaten Gorontalo | B25: PENGUNGKIT | C25: 3 | D25: PENATAAN SISTEM MANAJEMEN SDM APARATUR | E25: i | F25: Perencanaan Kebutuhan Pegawai sesuai dengan Kebutuhan Organisasi | G25: A.3.i.c | H25: Telah dilakukan monitoring dan dan evaluasi terhadap penempatan pegawai rekrutmen untuk memenuhi kebutuhan jabatan dalam organisasi telah memberikan perbaikan terhadap kinerja unit kerja | I25: Tidak | J25: 0 | L25: Belum ada: 1. Laporan Monev Kebutuhan Pegawai 2.Dokumentasi Rapat Evaluasi Kebutuhan Pegawai ( Undangan, Daftar Hadir, Foto, Notulen) | M25: — | N25: — | O25: — | Q25: https://drive.google.com/drive/folders/1wbQo-FCMpiZZj1hQn_RSGPDPEphjWY-c | R25: 38
A26: Kantah Kabupaten Gorontalo | B26: PENGUNGKIT | C26: 3 | D26: PENATAAN SISTEM MANAJEMEN SDM APARATUR | E26: ii | F26: Pola Mutasi Internal | G26: A.3.ii.a | H26: Dalam melakukan pengembangan karier pegawai, telah dilakukan mutasi pegawai antar jabatan | I26: Ya | J26: 1 | L26: Belum ada SK Mutasi PNS | M26: — | N26: — | O26: — | Q26: https://drive.google.com/drive/folders/12S57yYiU_46m7FIJ-rp9KjZnnetQGekd?usp=drive_link | R26: 40
A27: Kantah Kabupaten Gorontalo | B27: PENGUNGKIT | C27: 3 | D27: PENATAAN SISTEM MANAJEMEN SDM APARATUR | E27: ii | F27: Pola Mutasi Internal | G27: A.3.ii.b | H27: Dalam melakukan mutasi pegawai antar jabatan telah memperhatikan kompetensi jabatan dan mengikuti pola mutasi yang telah ditetapkan | I27: B | J27: 0.75 | L27: Tambahkan eviden yang lebih relevan. Bisa dilampirkan: 1. Laporan Monev Kebutuhan Pegawai 2.Dokumentasi Rapat Evaluasi Kebutuhan Pegawai ( Undangan, Daftar Hadir, Foto, Notulen) 3, SK Mutasi JFU, JFT, Pejabat struktural 4. Lampiran pengumuman KRS | M27: — | N27: — | O27: — | Q27: https://drive.google.com/drive/folders/13Zh-ErS4w6uLlTdgAujOzej3ByZ_4e40?usp=drive_link | R27: 41
A28: Kantah Kabupaten Gorontalo | B28: PENGUNGKIT | C28: 3 | D28: PENATAAN SISTEM MANAJEMEN SDM APARATUR | E28: ii | F28: Pola Mutasi Internal | G28: A.3.ii.c | H28: Telah dilakukan monitoring dan evaluasi terhadap kegiatan mutasi yang telah dilakukan dalam kaitannya dengan perbaikan kinerja | I28: Ya | J28: 1 | L28: Belum ada eviden diupload. Eviden diuraikan di kolom Cararan/Keterangan/Penjelasan Unit. Bisa dilampirkan: 1. SK Perpindahan JF 2. SK Pengangkatan Pejabat Pelaksana 3. Laporan Monev Mutasi (undangan, daftar hadir, notulen) | M28: — | N28: — | O28: — | Q28: https://drive.google.com/drive/folders/1-jDJI5Sss7nNt4vSAV5ve6JhsRsRQDrE?usp=drive_link | R28: 42
A29: Kantah Kabupaten Gorontalo | B29: PENGUNGKIT | C29: 3 | D29: PENATAAN SISTEM MANAJEMEN SDM APARATUR | E29: iii | F29: Pengembangan Pegawai Berbasis Kompetensi | G29: A.3.iii.a | H29: Unit Kerja melakukan Training Need Analysis Untuk pengembangan kompetensi | I29: Tidak | J29: 0 | L29: Belum ada eviden diupload. Eviden diuraikan di kolom Cararan/Keterangan/Penjelasan Unit. Bisa dilampirkan: 1. Analisis Kebutuhan Diklat 2. Surat Tugas dan Sertifikat Diklat 3. Table Analisis Kesenjangan Kompetensi ASN 4. Rekap pegawai mengikuti diklat | M29: — | N29: — | O29: — | R29: 44
A30: Kantah Kabupaten Gorontalo | B30: PENGUNGKIT | C30: 3 | D30: PENATAAN SISTEM MANAJEMEN SDM APARATUR | E30: iii | F30: Pengembangan Pegawai Berbasis Kompetensi | G30: A.3.iii.b | H30: Dalam menyusun rencana pengembangan kompetensi pegawai, telah mempertimbangkan hasil pengelolaan kinerja pegawai | I30: B | J30: 0.67 | L30: Kekurangan eviden: 1. Daftar Nominatif Penilaian Prestasi Kerja Pegawai (SKP) 2. Laporan Analisis Kebutuhan Diklat 4. Surat Tugas pemanggilan diklat 5. Daftar diklat yang telah dilakukan pegawai 7. Surat Keputusan Tim Penilai pegawai teladan | M30: — | N30: — | O30: — | Q30: https://drive.google.com/drive/folders/15K8iSKatdTcyGoXS3bHChSZwF7mw35V6?usp=drive_link | R30: 45
A31: Kantah Kabupaten Gorontalo | B31: PENGUNGKIT | C31: 3 | D31: PENATAAN SISTEM MANAJEMEN SDM APARATUR | E31: iii | F31: Pengembangan Pegawai Berbasis Kompetensi | G31: A.3.iii.c | H31: Tingkat kesenjangan kompetensi pegawai yang ada dengan standar kompetensi yang ditetapkan untuk masing-masing jabatan | I31: A | J31: 1 | L31: Tambahkan Dokumen : 1. Table perbandingan kesenjangan (GAP) kompetensi (IP ASN) 3. PK Kakanwil, Es 3, Es 4 dan JF | M31: — | N31: — | O31: — | Q31: https://drive.google.com/drive/folders/1czYmT5IeVlSC0hImb-2VeK-KqwBSM8Uf?usp=drive_link | R31: 46
A32: Kantah Kabupaten Gorontalo | B32: PENGUNGKIT | C32: 3 | D32: PENATAAN SISTEM MANAJEMEN SDM APARATUR | E32: iii | F32: Pengembangan Pegawai Berbasis Kompetensi | G32: A.3.iii.d | H32: Pegawai di Unit Kerja telah memperoleh kesempatan/hak untuk mengikuti diklat maupun pengembangan kompetensi lainnya | I32: B | J32: 0.67 | L32: Upload dokumen: 1. Usul pengembangan kompetensi pegawai 2. Surat pemanggilan diklat 3. ST diklat 4. Rekapitulasi diklat yang sudah diikuti, kebutuhan diklat 5. Dokumentasi diklat 6. Sertifikat diklat | M32: — | N32: — | O32: — | Q32: https://drive.google.com/drive/folders/1o9iet0ki69ypbVB1HKW9GUEf5x7ikiUV?usp=drive_link | R32: 47
A33: Kantah Kabupaten Gorontalo | B33: PENGUNGKIT | C33: 3 | D33: PENATAAN SISTEM MANAJEMEN SDM APARATUR | E33: iii | F33: Pengembangan Pegawai Berbasis Kompetensi | G33: A.3.iii.e | H33: Dalam pelaksanaan pengembangan kompetensi, unit kerja melakukan upaya pengembangan kompetensi kepada pegawai (seperti pengikutsertaan pada lembaga pelatihan, in-house training, coaching, atau mentoring) | I33: B | J33: 0.67 | L33: Perbanyak dokumen: 1. Usul pengembangan kompetensi pegawai 2. Surat pemanggilan diklat 3. ST diklat 5. Dokumentasi diklat 6. Sertifikat diklat | M33: — | N33: — | O33: — | Q33: https://drive.google.com/drive/folders/1iYe7oNDndgeCOdlMqakrFGsNOuC3tVxh?usp=drive_link | R33: 48
A34: Kantah Kabupaten Gorontalo | B34: PENGUNGKIT | C34: 3 | D34: PENATAAN SISTEM MANAJEMEN SDM APARATUR | E34: iii | F34: Pengembangan Pegawai Berbasis Kompetensi | G34: A.3.iii.f | H34: Telah dilakukan monitoring dan evaluasi terhadap hasil pengembangan kompetensi dalam kaitannya dengan perbaikan kinerja | I34: B | J34: 0.5 | L34: Upload dokumen: Update Dokumen : 1. Laporan Monitoring dan evaluasi pengembangan kompetensi 2. Dokumentasi (undangan, daftar hadir, notulen) | M34: — | N34: — | O34: — | Q34: https://drive.google.com/drive/folders/1LHBQENr_QcqVWpAvGPh60Gawr8q8bOqQ?usp=drive_link | R34: 49
A35: Kantah Kabupaten Gorontalo | B35: PENGUNGKIT | C35: 3 | D35: PENATAAN SISTEM MANAJEMEN SDM APARATUR | E35: iv | F35: Penetapan Kinerja Individu | G35: A.3.iv.a | H35: Terdapat penetapan kinerja individu yang terkait dengan perjanjian kinerja organisasi | I35: C | J35: 0.33 | L35: Link Evidence digabung menjadi 1 link yang berisi Folder eviden masing-masing tahun. Lengkapi: 2. Matriks peran hasil 3. PK Kakanwil, Es 3, Es 4 dan JF | M35: — | N35: — | O35: — | Q35: https://drive.google.com/drive/folders/1W2kgyF01kTKvqDeVK4e1DI0DISi1PY5G?usp=drive_link | R35: 51
A36: Kantah Kabupaten Gorontalo | B36: PENGUNGKIT | C36: 3 | D36: PENATAAN SISTEM MANAJEMEN SDM APARATUR | E36: iv | F36: Penetapan Kinerja Individu | G36: A.3.iv.b | H36: Ukuran kinerja individu telah memiliki kesesuaian dengan indikator kinerja individu level diatasnya | I36: C | J36: 0.33 | L36: Lengkapi: 1. Matriks Peran Hasil 2. Rekap Nominatif nilai skp | M36: — | N36: — | O36: — | Q36: https://drive.google.com/drive/folders/1sXzNhzVQbUzsb-uSJjLepGbu5jxdrUM1?usp=drive_link | R36: 52
A37: Kantah Kabupaten Gorontalo | B37: PENGUNGKIT | C37: 3 | D37: PENATAAN SISTEM MANAJEMEN SDM APARATUR | E37: iv | F37: Penetapan Kinerja Individu | G37: A.3.iv.c | H37: Pengukuran kinerja individu dilakukan secara periodik | I37: A | J37: 1 | L37: Link Evidence digabung menjadi 1 link yang berisi Folder eviden masing-masing tahun. eviden yang diuraikan belum ada. Lengkapi: 1. Lampirkan Rekap nominatif SKP 2. Laporan Kinerja bulanan P3K jika ada | M37: — | N37: — | O37: — | Q37: https://drive.google.com/drive/folders/1nTCXjO9wghh3b_uMN8g-8lSX7lY4KtiJ?usp=drive_link | R37: 53
A38: Kantah Kabupaten Gorontalo | B38: PENGUNGKIT | C38: 3 | D38: PENATAAN SISTEM MANAJEMEN SDM APARATUR | E38: iv | F38: Penetapan Kinerja Individu | G38: A.3.iv.d | H38: Hasil penilaian kinerja individu telah dijadikan dasar untuk pemberian reward | I38: Ya | J38: 1 | L38: Kekurangan: 1. Dokumentasi Reward 2. Bisa berupa SK Mutasi/ Promosi | M38: — | N38: — | O38: — | Q38: https://drive.google.com/drive/folders/16Kx_zfFJGeyPSHfnP04zHmOWgcQkpKwo?usp=drive_link | R38: 54
A39: Kantah Kabupaten Gorontalo | B39: PENGUNGKIT | C39: 3 | D39: PENATAAN SISTEM MANAJEMEN SDM APARATUR | E39: v | F39: Penegakan Aturan Disiplin/Kode Etik/Kode Perilaku Pegawai | G39: A.3.v.a | H39: Aturan disiplin/kode etik/kode perilaku telah dilaksanakan/diimplementasikan | I39: B | J39: 0.67 | L39: Belum ada inovasi | M39: — | N39: — | O39: — | Q39: https://drive.google.com/drive/folders/1a2CwaWBVZ6a7L8v430NuV3KMa8YhuqTy | R39: 56
A40: Kantah Kabupaten Gorontalo | B40: PENGUNGKIT | C40: 3 | D40: PENATAAN SISTEM MANAJEMEN SDM APARATUR | E40: vi | F40: Sistem Informasi Kepegawaian | G40: A.3.vi.a | H40: Data informasi kepegawaian unit kerja telah dimutakhirkan secara berkala | I40: B | J40: 0.5 | L40: Isi uraian evidence. Ikuti contoh LKE Kota: https://drive.google.com/drive/folders/1O3W-XKHpu8LqW1b1Sbl1jw8QlkhD3j30 | M40: — | N40: — | O40: — | Q40: https://drive.google.com/drive/folders/1USj1_2RDhFamb9CWvZXw5DzlS0yEAwQs | R40: 58
...

Sheet Lists
A1: Satker | B1: Komponen | D1: Komponen Pengungkit
A2: Kantah Kabupaten Gorontalo | B2: MANAJEMEN PERUBAHAN | D2: MANAJEMEN PERUBAHAN
A3: Kanwil BPN Provinsi Gorontalo | B3: PENATAAN TATALAKSANA | D3: PENATAAN TATALAKSANA
B4: PENATAAN SISTEM MANAJEMEN SDM APARATUR | D4: PENATAAN SISTEM MANAJEMEN SDM APARATUR
B5: PENGUATAN AKUNTABILITAS | D5: PENGUATAN AKUNTABILITAS
B6: PENGUATAN PENGAWASAN | D6: PENGUATAN PENGAWASAN
B7: PENINGKATAN KUALITAS PELAYANAN PUBLIK | D7: PENINGKATAN KUALITAS PELAYANAN PUBLIK
B8: BIROKRASI YANG BERSIH DAN AKUNTABEL
B9: PELAYANAN PUBLIK YANG PRIMA

Sheet Data_Area
A1: Satker | B1: Section | C1: No | D1: Komponen | E1: Bobot | F1: Nilai | G1: Pct
A2: Kantah Kabupaten Gorontalo | B2: PENGUNGKIT | C2: 1 | D2: MANAJEMEN PERUBAHAN | E2: 8 | F2: 6.1329167 | G2: 0.76661458
A3: Kantah Kabupaten Gorontalo | B3: PENGUNGKIT | C3: 2 | D3: PENATAAN TATALAKSANA | E3: 7 | F3: 4.68 | G3: 0.66857143
A4: Kantah Kabupaten Gorontalo | B4: PENGUNGKIT | C4: 3 | D4: PENATAAN SISTEM MANAJEMEN SDM APARATUR | E4: 10 | F4: 6.03625 | G4: 0.603625
A5: Kantah Kabupaten Gorontalo | B5: PENGUNGKIT | C5: 4 | D5: PENGUATAN AKUNTABILITAS | E5: 10 | F5: 9.34875 | G5: 0.934875
A6: Kantah Kabupaten Gorontalo | B6: PENGUNGKIT | C6: 5 | D6: PENGUATAN PENGAWASAN | E6: 15 | F6: 10.088 | G6: 0.67253333
A7: Kantah Kabupaten Gorontalo | B7: PENGUNGKIT | C7: 6 | D7: PENINGKATAN KUALITAS PELAYANAN PUBLIK | E7: 10 | F7: 9.1516667 | G7: 0.91516667
A8: Kantah Kabupaten Gorontalo | B8: HASIL | C8: 1 | D8: BIROKRASI YANG BERSIH DAN AKUNTABEL | E8: 22.5 | F8: 19.890625 | G8: 0.88402778
A9: Kantah Kabupaten Gorontalo | B9: HASIL | C9: 2 | D9: PELAYANAN PUBLIK YANG PRIMA | E9: 17.5 | F9: 17.4125 | G9: 0.995
A10: Kanwil BPN Provinsi Gorontalo | B10: PENGUNGKIT | C10: 1 | D10: MANAJEMEN PERUBAHAN | E10: 8 | F10: 6.655 | G10: 0.831875
A11: Kanwil BPN Provinsi Gorontalo | B11: PENGUNGKIT | C11: 2 | D11: PENATAAN TATALAKSANA | E11: 7 | F11: 4.5 | G11: 0.64285714
A12: Kanwil BPN Provinsi Gorontalo | B12: PENGUNGKIT | C12: 3 | D12: PENATAAN SISTEM MANAJEMEN SDM APARATUR | E12: 10 | F12: 9.0858333 | G12: 0.90858333
A13: Kanwil BPN Provinsi Gorontalo | B13: PENGUNGKIT | C13: 4 | D13: PENGUATAN AKUNTABILITAS | E13: 10 | F13: 8.8133333 | G13: 0.88133333
... A17: Kanwil BPN Provinsi Gorontalo | B17: HASIL | C17: 2 | D17: PELAYANAN PUBLIK YANG PRIMA | E17: 17.5 | F17: 17.325 | G17: 0.99
